Workbook

Sheet Summary
B4: Summary - Progress testing
C6: Passed | D6: Failed | E6: N/A | F6: Blocked | G6: Not test yet | H6: Sum | I6: Progress
B7: JEC-8 | C7: =COUNTIF(TCs!I12:I596, "Passed") -> 0 | D7: =COUNTIF(TCs!I12:I596, "Failed") -> 0 | E7: =COUNTIF(TCs!I12:I596, "N/A") -> 0 | F7: =COUNTIF(TCs!I12:I596, "Blocked") -> 0 | G7: =COUNTIF(TCs!I12:I596, "Not test yet") -> 0 | H7: =COUNTIF(TCs!I12:I596, "*") -> 0 | I7: =SUM(C7, E7)/H7 -> #DIV/0!

Sheet TCs
C2: Priority | F2: Notes: Have to update the P1 test case before the function is merged to UAT
C3: 1 | D3: Very High | E3: Main flow: Full workflow on web (to mobile), Validate required field, Docxtag
C4: 2 | D4: High | E4: Functional cases, component check cases, Additional function cases, Related function cases, Validation cases.
C5: 3 | D5: Medium | E5: Unhappy cases, Edge Cases, Exception cases, Permission
C6: 4 | D6: Low | E6: UI cases, Rare cases
C9: Ticket ID
A11: Requirement | B11: No. | C11: Title | D11: Steps | E11: Steps expected result | F11: Priority | G11: Tags | H11: Area Path | I11: Status | J11: Note
B12: =IF(C12="","",SUBTOTAL(3,$C$12:C12)) -> 1 | C12: Setting - Staff - Administrator - New permissions are added and granted for administrator user in Advanced tab | F12: 1 | G12: JEC-8, CGroupInvoice | H12: TMS\QC Team\JLWeb Test Cases\Invoices
B13: =IF(C13="","",SUBTOTAL(3,$C$12:C13)) | D13: Precondition: 1. Existed Administrator users (E.g. Admin A)
D14: Navigate to Setting > Staff > Manage User Roles
B15: =IF(C15="","",SUBTOTAL(3,$C$12:C15)) | D15: Select Administrator role > Open details
D16: Click on [Advanced] tab > Verify | E16: The new permissions added and granted: - Invoice - Delete Draft - Invoice - Batch Delete Draft - Customer Grouped Invoice - Delete Draft - Batch of Invoice - Delete Draft Batch - PPM - Delete Draft Invoice - Credit - Delete Draft - Contract Purchase Order - Delete Draft Contract Credit
D17: Navigate to Membesr in Role details (E.g. Admin A)
D18: Verify permissions in Advanced | E18: All new permission [Inherit] in role granted from Admin - Invoice - Delete Draft - Invoice - Batch Delete Draft - Customer Grouped Invoice - Delete Draft - Batch of Invoice - Delete Draft Batch - PPM - Delete Draft Invoice - Credit - Delete Draft - Contract Purchase Order - Delete Draft Contract Credit Table
D19: Create new Admin user > Verify permission in Advance tab | E19: All new permission auto [Inherit] in role granted from Admin - Invoice - Delete Draft - Invoice - Batch Delete Draft - Customer Grouped Invoice - Delete Draft - Batch of Invoice - Delete Draft Batch - PPM - Delete Draft Invoice - Credit - Delete Draft - Contract Purchase Order - Delete Draft Contract Credit Table
D20: Login to JL Web as user this role > Verify on Draft Invoice or Draft Create | E20: This user role able to delete Drafts by default
D21: Try to update in role > make denied permissions for Admin user > Verify | E21: The user NOT able to delete Drafts
B22: =IF(C22="","",SUBTOTAL(3,$C$12:C22)) -> 2 | C22: Setting - Staff - Engineer - New permissions are added and Denied for Engineer user in Advanced tab | F22: 1 | G22: JEC-8, CGroupInvoice | H22: TMS\QC Team\JLWeb Test Cases\Invoices
B23: =IF(C23="","",SUBTOTAL(3,$C$12:C23)) | D23: Precondition: 1. Existed Engineer users (E.g. Engineer E1)
D24: Navigate to Setting > Staff > Manage User Roles
B25: =IF(C25="","",SUBTOTAL(3,$C$12:C25)) | D25: Select Engineer role > Open details
D26: Click on [Advanced] tab > Verify | E26: The new permissions added and Denied: Invoice - Delete Draft Invoice - Batch Delete Draft Customer Grouped Invoice - Delete Draft Batch of Invoice - Delete Draft Batch PPM - Delete Draft Invoice
D27: Navigate to Membesr in Role details (E.g. Engineer E1)
D28: Verify permissions in Advanced | E28: All new permission [Inherit] in role denied from Engineer role - Invoice - Delete Draft - Invoice - Batch Delete Draft - Customer Grouped Invoice - Delete Draft - Batch of Invoice - Delete Draft Batch - PPM - Delete Draft Invoice - Credit - Delete Draft - Contract Purchase Order - Delete Draft Contract Credit Table
D29: Create new Engineer user > Verify permission in Advance tab | E29: All new permission auto [Inherit] in role denied from Engineer role - Invoice - Delete Draft - Invoice - Batch Delete Draft - Customer Grouped Invoice - Delete Draft - Batch of Invoice - Delete Draft Batch - PPM - Delete Draft Invoice - Credit - Delete Draft - Contract Purchase Order - Delete Draft Contract Credit Table
D30: Login to JL Web as user this role > Verify on Draft Invoice or Draft Create | E30: This user role NOT able to delete Drafts as by default
D31: Try to update in role > Grant permissions for Engineer user > Verify | E31: The user can be delete Drafts
B32: =IF(C32="","",SUBTOTAL(3,$C$12:C32)) -> 3 | C32: Setting - Staff - Costing user - New permissions are added and Denied for Costing user user in Advanced tab | F32: 1 | G32: JEC-8, CGroupInvoice | H32: TMS\QC Team\JLWeb Test Cases\Invoices
B33: =IF(C33="","",SUBTOTAL(3,$C$12:C33)) | D33: Precondition: 1. Existed Costing users (E.g. Costing user C1)
B34: =IF(C34="","",SUBTOTAL(3,$C$12:C34)) | D34: Navigate to Setting > Staff > Manage User Roles
D35: Select Costing user role > Open details
D36: Click on [Advanced] tab > Verify | E36: The new permissions added and Denied: Invoice - Delete Draft Invoice - Batch Delete Draft Customer Grouped Invoice - Delete Draft Batch of Invoice - Delete Draft Batch PPM - Delete Draft Invoice
D37: Navigate to Membesr in Role details (E.g. Costing user C1)
D38: Verify permissions in Advanced | E38: All new permission [Inherit] in role denied from Costing role - Invoice - Delete Draft - Invoice - Batch Delete Draft - Customer Grouped Invoice - Delete Draft - Batch of Invoice - Delete Draft Batch - PPM - Delete Draft Invoice - Credit - Delete Draft - Contract Purchase Order - Delete Draft Contract Credit Table
D39: Create new Costing user > Verify permission in Advance tab | E39: All new permission auto [Inherit] in role denied from Costing user role - Invoice - Delete Draft - Invoice - Batch Delete Draft - Customer Grouped Invoice - Delete Draft - Batch of Invoice - Delete Draft Batch - PPM - Delete Draft Invoice - Credit - Delete Draft - Contract Purchase Order - Delete Draft Contract Credit Table
D40: Login to JL Web as user this role > Verify on Draft Invoice or Draft Create | E40: This user role NOT able to delete Drafts as by default
D41: Try to update in role > Grant permissions for Costing user > Verify | E41: The user can be delete Drafts
B42: =IF(C42="","",SUBTOTAL(3,$C$12:C42)) -> 4 | C42: Setting - Staff - Job Desk user - New permissions are added and Denied for Job Desk user in Advanced tab | F42: 1 | G42: JEC-8, CGroupInvoice | H42: TMS\QC Team\JLWeb Test Cases\Invoices
B43: =IF(C43="","",SUBTOTAL(3,$C$12:C43)) | D43: Precondition: 1. Existed Job desk users (E.g. Job desk user D1)
B44: =IF(C44="","",SUBTOTAL(3,$C$12:C44)) | D44: Navigate to Setting > Staff > Manage User Roles
...

Sheet Data
B2: Area Path | D2: Status
B3: TMS\QC Team\JLWeb Test Cases\Registration and Login | D3: Passed
B4: TMS\QC Team\JLWeb Test Cases\Activation | D4: Failed
B5: TMS\QC Team\JLWeb Test Cases\Customers | D5: N/A
B6: TMS\QC Team\JLWeb Test Cases\Sites | D6: Blocked
B7: TMS\QC Team\JLWeb Test Cases\Assets | D7: Not test yet
B8: TMS\QC Team\JLWeb Test Cases\Jobs
B9: TMS\QC Team\JLWeb Test Cases\Quotes | D9: Priority
B10: TMS\QC Team\JLWeb Test Cases\Invoices | D10: 1
B11: TMS\QC Team\JLWeb Test Cases\PPM | D11: 2
B12: TMS\QC Team\JLWeb Test Cases\PO | D12: 3
B13: TMS\QC Team\JLWeb Test Cases\Reports | D13: 4
B14: TMS\QC Team\JLWeb Test Cases\Projects
B15: TMS\QC Team\JLWeb Test Cases\Engineers
B16: TMS\QC Team\JLWeb Test Cases\Engineers\Engineer List
B17: TMS\QC Team\JLWeb Test Cases\Engineers\All NPT
B18: TMS\QC Team\JLWeb Test Cases\Engineers\View Planner
B19: TMS\QC Team\JLWeb Test Cases\Engineers\Timesheets
B20: TMS\QC Team\JLWeb Test Cases\Engineers\Route Schedule
B21: TMS\QC Team\JLWeb Test Cases\Engineers\Live Tracking
B22: TMS\QC Team\JLWeb Test Cases\Engineers\History Tracking
B23: TMS\QC Team\JLWeb Test Cases\Forms Logbook
B24: TMS\QC Team\JLWeb Test Cases\Refcom
B25: TMS\QC Team\JLWeb Test Cases\Stock
... B35: TMS\QC Team\JLWeb Test Cases\Dashboard
